<?xml version="1.0" ?>
<!-- =================================================================================== -->
<!-- |    This document was autogenerated by xacro from /home/evence/arx/ros2_ws/src/ARX_urdf/xacro/x7_lift/lift_for_urdf.xacro | -->
<!-- |    EDITING THIS FILE BY HAND IS NOT RECOMMENDED                                 | -->
<!-- =================================================================================== -->
<robot name="lift">
  <material name="silver">
    <color rgba="0.700 0.700 0.700 1.000"/>
  </material>
  <link name="base_link">
    <inertial>
      <origin rpy="0 0 0" xyz="0.015300075250394498 -0.0039712791148939055 0.21685783167580347"/>
      <mass value="67.7696558151508"/>
      <inertia ixx="7.900786" ixy="-0.021075" ixz="0.25289" iyy="8.068966" iyz="0.12408" izz="2.254894"/>
    </inertial>
    <visual>
      <origin rpy="-2.0650148258027962e-14 -5.495603971894524e-15 -1.570796326794892" xyz="-0.02589436313797319 -0.09143146519519073 0.05911679497216196"/>
      <geometry>
        <mesh filename="../meshes/lift/base_link.stl" scale="0.001 0.001 0.001"/>
      </geometry>
      <material name="silver"/>
    </visual>
    <collision>
      <origin rpy="-2.0650148258027962e-14 -5.495603971894524e-15 -1.570796326794892" xyz="-0.02589436313797319 -0.09143146519519073 0.05911679497216196"/>
      <geometry>
        <mesh filename="../meshes/lift/base_link.stl" scale="0.001 0.001 0.001"/>
      </geometry>
    </collision>
  </link>
  <link name="wheel_1">
    <inertial>
      <origin rpy="0 0 0" xyz="-0.0013052205916280202 0.0022598671755268973 1.318970376112949e-07"/>
      <mass value="4.24803000494366"/>
      <inertia ixx="0.008031" ixy="-0.002428" ixz="0.0" iyy="0.010834" iyz="0.0" izz="0.006629"/>
    </inertial>
    <visual>
      <origin rpy="0 0 0" xyz="0.182349 -0.315838 -0.03"/>
      <geometry>
        <mesh filename="../meshes/lift/wheel_1.stl" scale="0.001 0.001 0.001"/>
      </geometry>
      <material name="silver"/>
    </visual>
    <collision>
      <origin rpy="0 0 0" xyz="0.182349 -0.315838 -0.03"/>
      <geometry>
        <mesh filename="../meshes/lift/wheel_1.stl" scale="0.001 0.001 0.001"/>
      </geometry>
    </collision>
  </link>
  <link name="wheel_2">
    <inertial>
      <origin rpy="0 0 0" xyz="-0.0013052205916208315 -0.0022598671755325594 -1.318970357273852e-07"/>
      <mass value="4.24803000494366"/>
      <inertia ixx="0.008031" ixy="0.002428" ixz="-0.0" iyy="0.010834" iyz="0.0" izz="0.006629"/>
    </inertial>
    <visual>
      <origin rpy="0 0 0" xyz="0.182349 0.315838 -0.03"/>
      <geometry>
        <mesh filename="../meshes/lift/wheel_2.stl" scale="0.001 0.001 0.001"/>
      </geometry>
      <material name="silver"/>
    </visual>
    <collision>
      <origin rpy="0 0 0" xyz="0.182349 0.315838 -0.03"/>
      <geometry>
        <mesh filename="../meshes/lift/wheel_2.stl" scale="0.001 0.001 0.001"/>
      </geometry>
    </collision>
  </link>
  <link name="wheel_3">
    <inertial>
      <origin rpy="0 0 0" xyz="0.0026089441594678298 -1.3189703553351252e-07 2.8695680726054107e-07"/>
      <mass value="4.24803000494366"/>
      <inertia ixx="0.012235" ixy="-0.0" ixz="0.0" iyy="0.006629" iyz="0.0" izz="0.006629"/>
    </inertial>
    <visual>
      <origin rpy="0 0 0" xyz="-0.364699 -0.0 -0.03"/>
      <geometry>
        <mesh filename="../meshes/lift/wheel_3.stl" scale="0.001 0.001 0.001"/>
      </geometry>
      <material name="silver"/>
    </visual>
    <collision>
      <origin rpy="0 0 0" xyz="-0.364699 -0.0 -0.03"/>
      <geometry>
        <mesh filename="../meshes/lift/wheel_3.stl" scale="0.001 0.001 0.001"/>
      </geometry>
    </collision>
  </link>
  <link name="lift_1">
    <inertial>
      <origin rpy="0 0 0" xyz="-0.13956899916103924 -0.07061717818525884 0.07323798891482189"/>
      <mass value="17.38744536890084"/>
      <inertia ixx="0.187458" ixy="-0.000206" ixz="0.023942" iyy="0.178157" iyz="-0.000153" izz="0.29708"/>
    </inertial>
    <visual>
      <origin rpy="-3.1415926535897922 -5.9119376061289625e-15 -1.570796326794892" xyz="0.23377630259911772 -0.9431740063510481 1.8984630014809656"/>
      <geometry>
        <mesh filename="../meshes/lift/lift.stl" scale="0.001 0.001 0.001"/>
      </geometry>
      <material name="silver"/>
    </visual>
    <collision>
      <origin rpy="-3.1415926535897922 -5.9119376061289625e-15 -1.570796326794892" xyz="0.23377630259911772 -0.9431740063510481 1.8984630014809656"/>
      <geometry>
        <mesh filename="../meshes/lift/lift.stl" scale="0.001 0.001 0.001"/>
      </geometry>
    </collision>
  </link>
  <joint name="joint_wheel1" type="continuous">
    <origin rpy="0 0 0" xyz="-0.182349 0.315838 0.03"/>
    <parent link="base_link"/>
    <child link="wheel_1"/>
    <axis xyz="-0.5 0.866025 0.0"/>
  </joint>
  <joint name="joint_wheel2" type="continuous">
    <origin rpy="0 0 0" xyz="-0.182349 -0.315838 0.03"/>
    <parent link="base_link"/>
    <child link="wheel_2"/>
    <axis xyz="-0.5 -0.866025 0.0"/>
  </joint>
  <joint name="joint_wheel3" type="continuous">
    <origin rpy="0 0 0" xyz="0.364699 0.0 0.03"/>
    <parent link="base_link"/>
    <child link="wheel_3"/>
    <axis xyz="1.0 0.0 -0.0"/>
  </joint>
  <joint name="joint_lift" type="prismatic">
    <origin rpy="0 0 0" xyz="0.022199 0.07 0.233"/>
    <parent link="base_link"/>
    <child link="lift_1"/>
    <axis xyz="0.0 0.0 1.0"/>
    <limit effort="100" lower="0.0" upper="0.86" velocity="100"/>
  </joint>
  <link name="h_base_link">
    <inertial>
      <origin rpy="0 0 0" xyz="-0.0020743076738515215 -1.5307881645835308e-08 -0.024619861716967787"/>
      <mass value="0.9930933606993821"/>
      <inertia ixx="0.000391" ixy="-0.0" ixz="1.7e-05" iyy="0.000452" iyz="0.0" izz="0.000532"/>
    </inertial>
    <visual>
      <origin rpy="-6.152630488421012e-15 -7.615436059539092e-16 -9.529963623799859e-14" xyz="-0.08527048097893797 -0.1374690238644495 1.311881544560024"/>
      <geometry>
        <mesh filename="../meshes/lift/h_base.stl" scale="0.001 0.001 0.001"/>
      </geometry>
      <material name="silver"/>
    </visual>
    <collision>
      <origin rpy="-6.152630488421012e-15 -7.615436059539092e-16 -9.529963623799859e-14" xyz="-0.08527048097893797 -0.1374690238644495 1.311881544560024"/>
      <geometry>
        <mesh filename="../meshes/lift/h_base.stl" scale="0.001 0.001 0.001"/>
      </geometry>
    </collision>
  </link>
  <link name="h_link1_1">
    <inertial>
      <origin rpy="0 0 0" xyz="-1.3121512495483172e-08 -0.0017956601536253606 -0.0404485568834118"/>
      <mass value="1.1585686692835446"/>
      <inertia ixx="0.000714" ixy="-0.0" ixz="0.0" iyy="0.000677" iyz="3.4e-05" izz="0.000524"/>
    </inertial>
    <visual>
      <origin rpy="-1.5707963267948963 -1.0061405783930931e-14 3.1415926535896976" xyz="-0.12236311194583296 0.2951630600814396 -0.7084366619197162"/>
      <geometry>
        <mesh filename="../meshes/lift/h_link1.stl" scale="0.001 0.001 0.001"/>
      </geometry>
      <material name="silver"/>
    </visual>
    <collision>
      <origin rpy="-1.5707963267948963 -1.0061405783930931e-14 3.1415926535896976" xyz="-0.12236311194583296 0.2951630600814396 -0.7084366619197162"/>
      <geometry>
        <mesh filename="../meshes/lift/h_link1.stl" scale="0.001 0.001 0.001"/>
      </geometry>
    </collision>
  </link>
  <link name="h_link2_1">
    <inertial>
      <origin rpy="0 0 0" xyz="0.03081593597576142 -0.022504711493597663 -0.0659240377971316"/>
      <mass value="1.5752562353484625"/>
      <inertia ixx="0.004555" ixy="0.000214" ixz="0.000252" iyy="0.004541" iyz="-0.000299" izz="0.00636"/>
    </inertial>
    <visual>
      <origin rpy="-2.7499378823653957e-16 1.0181092080507767e-14 -9.236457240818265e-14" xyz="-0.08527048097895003 -0.16246902386446574 1.4048815445600387"/>
      <geometry>
        <mesh filename="../meshes/lift/h_link2.stl" scale="0.001 0.001 0.001"/>
      </geometry>
      <material name="silver"/>
    </visual>
    <collision>
      <origin rpy="-2.7499378823653957e-16 1.0181092080507767e-14 -9.236457240818265e-14" xyz="-0.08527048097895003 -0.16246902386446574 1.4048815445600387"/>
      <geometry>
        <mesh filename="../meshes/lift/h_link2.stl" scale="0.001 0.001 0.001"/>
      </geometry>
    </collision>
  </link>
  <joint name="joint_h_1" type="continuous">
    <origin rpy="0 0 0" xyz="0.0 0.0 -0.046"/>
    <parent link="h_base_link"/>
    <child link="h_link1_1"/>
    <axis xyz="0.0 -0.0 1.0"/>
  </joint>
  <joint name="joint_h_2" type="continuous">
    <origin rpy="0 0 0" xyz="0.0 0.025 -0.047"/>
    <parent link="h_link1_1"/>
    <child link="h_link2_1"/>
    <axis xyz="-0.0 -1.0 0.0"/>
  </joint>
  <joint name="h_fixed" type="fixed">
    <!-- 父链接 -->
    <parent link="lift_1"/>
    <!-- 子链接 -->
    <child link="h_base_link"/>
    <!-- 关节的位置和方向（例如原点、方向）-->
    <origin rpy="0 3.1415926 0" xyz="-0.258786 -0.07000 0.220008"/>
  </joint>
  <link name="left_arm_base_link">
    <inertial>
      <origin rpy="0 0 0" xyz="-0.0001456050150032109 -7.271800715889125e-05 -0.03159354340734995"/>
      <mass value="1.1276471378072246"/>
      <inertia ixx="0.000524" ixy="-1e-06" ixz="2e-06" iyy="0.000527" iyz="-2e-06" izz="0.000538"/>
    </inertial>
    <visual>
      <origin rpy="-1.57079632679489 -5.682641097165828e-13 1.4835298641951802" xyz="0.007409306349121554 -0.041273942276757764 -0.09300023656190275"/>
      <geometry>
        <mesh filename="../meshes/lift/arm_base_link.stl" scale="0.001 0.001 0.001"/>
      </geometry>
      <material name="silver"/>
    </visual>
    <collision>
      <origin rpy="-1.57079632679489 -5.682641097165828e-13 1.4835298641951802" xyz="0.007409306349121554 -0.041273942276757764 -0.09300023656190275"/>
      <geometry>
        <mesh filename="../meshes/lift/arm_base_link.stl" scale="0.001 0.001 0.001"/>
      </geometry>
    </collision>
  </link>
  <link name="left_arm_left_catch">
    <inertial>
      <origin rpy="0 0 0" xyz="0.022696371000088422 0.06755851746973854 0.008381661910845134"/>
      <mass value="0.25047156301061513"/>
      <inertia ixx="9.7e-05" ixy="-1.6e-05" ixz="9e-06" iyy="0.000157" iyz="-3e-06" izz="0.000137"/>
    </inertial>
    <visual>
      <origin rpy="-1.5707963267948564 -5.674274719459635e-13 1.483529864195179" xyz="-0.2827978086885289 -0.2179220999653169 -0.13086553021673955"/>
      <geometry>
        <mesh filename="../meshes/lift/arm_left_catch.stl" scale="0.001 0.001 0.001"/>
      </geometry>
      <material name="silver"/>
    </visual>
    <collision>
      <origin rpy="-1.5707963267948564 -5.674274719459635e-13 1.483529864195179" xyz="-0.2827978086885289 -0.2179220999653169 -0.13086553021673955"/>
      <geometry>
        <mesh filename="../meshes/lift/arm_left_catch.stl" scale="0.001 0.001 0.001"/>
      </geometry>
    </collision>
  </link>
  <link name="left_arm_right_catch">
    <inertial>
      <origin rpy="0 0 0" xyz="0.01062064996036352 -0.0704739510881078 0.0022902966101032707"/>
      <mass value="0.2504715624632503"/>
      <inertia ixx="0.000107" ixy="2.5e-05" ixz="-1.9e-05" iyy="0.000152" iyz="3e-06" izz="0.000137"/>
    </inertial>
    <visual>
      <origin rpy="-1.5707963267948528 -5.674877622823835e-13 1.4835298641951784" xyz="-0.3341410986133092 -0.4899139341993404 -0.028033322065217275"/>
      <geometry>
        <mesh filename="../meshes/lift/arm_right_catch.stl" scale="0.001 0.001 0.001"/>
      </geometry>
      <material name="silver"/>
    </visual>
    <collision>
      <origin rpy="-1.5707963267948528 -5.674877622823835e-13 1.4835298641951784" xyz="-0.3341410986133092 -0.4899139341993404 -0.028033322065217275"/>
      <geometry>
        <mesh filename="../meshes/lift/arm_right_catch.stl" scale="0.001 0.001 0.001"/>
      </geometry>
    </collision>
  </link>
  <link name="left_arm_link6">
    <inertial>
      <origin rpy="0 0 0" xyz="0.04606151123037028 -0.00403375833742786 -0.02029844922950161"/>
      <mass value="1.6175866280512115"/>
      <inertia ixx="0.002554" ixy="1e-05" ixz="0.000717" iyy="0.002684" iyz="-5.6e-05" izz="0.001423"/>
    </inertial>
    <visual>
      <origin rpy="-3.1415926535897496 -5.674609506829504e-13 1.4835298641951782" xyz="0.07015096496844125 -0.0940377631493199 0.017299995001154284"/>
      <geometry>
        <mesh filename="../meshes/lift/arm_link6.stl" scale="0.001 0.001 0.001"/>
      </geometry>
      <material name="silver"/>
    </visual>
    <collision>
      <origin rpy="-3.1415926535897496 -5.674609506829504e-13 1.4835298641951782" xyz="0.07015096496844125 -0.0940377631493199 0.017299995001154284"/>
      <geometry>
        <mesh filename="../meshes/lift/arm_link6.stl" scale="0.001 0.001 0.001"/>
      </geometry>
    </collision>
  </link>
  <link name="left_arm_link5">
    <inertial>
      <origin rpy="0 0 0" xyz="0.0035114951739801253 -0.00032438367383951644 0.05339769316683546"/>
      <mass value="1.682735565009155"/>
      <inertia ixx="0.002208" ixy="-3e-06" ixz="-0.000168" iyy="0.002158" iyz="1.4e-05" izz="0.000703"/>
    </inertial>
    <visual>
      <origin rpy="-3.110107982315251e-13 5.550755306658921e-13 -1.3581133125663458" xyz="0.030052794300312463 -0.05494208160627965 -0.057241042913650286"/>
      <geometry>
        <mesh filename="../meshes/lift/arm_link5.stl" scale="0.001 0.001 0.001"/>
      </geometry>
      <material name="silver"/>
    </visual>
    <collision>
      <origin rpy="-3.110107982315251e-13 5.550755306658921e-13 -1.3581133125663458" xyz="0.030052794300312463 -0.05494208160627965 -0.057241042913650286"/>
      <geometry>
        <mesh filename="../meshes/lift/arm_link5.stl" scale="0.001 0.001 0.001"/>
      </geometry>
    </collision>
  </link>
  <link name="left_arm_link4">
    <inertial>
      <origin rpy="0 0 0" xyz="0.039690032456672866 -0.025382085939758787 -0.033369810917050824"/>
      <mass value="0.3614635103426687"/>
      <inertia ixx="0.000648" ixy="6.6e-05" ixz="0.000254" iyy="0.000701" iyz="-8.5e-05" izz="0.000483"/>
    </inertial>
    <visual>
      <origin rpy="-1.5707963267948528 -5.678466258263498e-13 1.4835298641951788" xyz="0.0005892853030446308 -0.027355392579593747 0.13399227229218344"/>
      <geometry>
        <mesh filename="../meshes/lift/arm_link4.stl" scale="0.001 0.001 0.001"/>
      </geometry>
      <material name="silver"/>
    </visual>
    <collision>
      <origin rpy="-1.5707963267948528 -5.678466258263498e-13 1.4835298641951788" xyz="0.0005892853030446308 -0.027355392579593747 0.13399227229218344"/>
      <geometry>
        <mesh filename="../meshes/lift/arm_link4.stl" scale="0.001 0.001 0.001"/>
      </geometry>
    </collision>
  </link>
  <link name="left_arm_link3">
    <inertial>
      <origin rpy="0 0 0" xyz="0.1464097574775916 -0.03950335038970569 -0.055156332017432905"/>
      <mass value="2.8273308884294726"/>
      <inertia ixx="0.002779" ixy="0.001761" ixz="0.002033" iyy="0.026162" iyz="-0.000192" izz="0.025936"/>
    </inertial>
    <visual>
      <origin rpy="-1.5707963267948528 -5.678273122036292e-13 1.4835298641951793" xyz="0.24465628530304592 -0.04875839257959501 0.07399227229217889"/>
      <geometry>
        <mesh filename="../meshes/lift/arm_link3.stl" scale="0.001 0.001 0.001"/>
      </geometry>
      <material name="silver"/>
    </visual>
    <collision>
      <origin rpy="-1.5707963267948528 -5.678273122036292e-13 1.4835298641951793" xyz="0.24465628530304592 -0.04875839257959501 0.07399227229217889"/>
      <geometry>
        <mesh filename="../meshes/lift/arm_link3.stl" scale="0.001 0.001 0.001"/>
      </geometry>
    </collision>
  </link>
  <link name="left_arm_link2">
    <inertial>
      <origin rpy="0 0 0" xyz="-0.13152163105173825 -0.014795828980240422 3.909377899950772e-05"/>
      <mass value="3.2738322976375356"/>
      <inertia ixx="0.002162" ixy="0.003924" ixz="-4e-06" iyy="0.043867" iyz="-0.0" izz="0.044191"/>
    </inertial>
    <visual>
      <origin rpy="-1.5707963267948528 -5.678165582083773e-13 1.4835298641951784" xyz="-0.018339714696967803 -0.02574939257965983 0.07399227229217917"/>
      <geometry>
        <mesh filename="../meshes/lift/arm_link2.stl" scale="0.001 0.001 0.001"/>
      </geometry>
      <material name="silver"/>
    </visual>
    <collision>
      <origin rpy="-1.5707963267948528 -5.678165582083773e-13 1.4835298641951784" xyz="-0.018339714696967803 -0.02574939257965983 0.07399227229217917"/>
      <geometry>
        <mesh filename="../meshes/lift/arm_link2.stl" scale="0.001 0.001 0.001"/>
      </geometry>
    </collision>
  </link>
  <link name="left_arm_link1">
    <inertial>
      <origin rpy="0 0 0" xyz="0.005695029028846315 0.007271965833248688 -0.020896953872813907"/>
      <mass value="0.2814477837021216"/>
      <inertia ixx="0.000303" ixy="-3e-05" ixz="3.9e-05" iyy="0.000139" iyz="2.9e-05" izz="0.00028"/>
    </inertial>
    <visual>
      <origin rpy="-1.570796326794885 -5.65543868255413e-13 1.4835298641951802" xyz="0.003959285303010329 -0.0003463925796654088 0.026992272292183782"/>
      <geometry>
        <mesh filename="../meshes/lift/arm_link1.stl" scale="0.001 0.001 0.001"/>
      </geometry>
      <material name="silver"/>
    </visual>
    <collision>
      <origin rpy="-1.570796326794885 -5.65543868255413e-13 1.4835298641951802" xyz="0.003959285303010329 -0.0003463925796654088 0.026992272292183782"/>
      <geometry>
        <mesh filename="../meshes/lift/arm_link1.stl" scale="0.001 0.001 0.001"/>
      </geometry>
    </collision>
  </link>
  <joint name="left_catch_joint1" type="prismatic">
    <origin rpy="0 0 0" xyz="0.067534 -0.091232 -0.005"/>
    <parent link="left_arm_link6"/>
    <child link="left_arm_left_catch"/>
    <axis xyz="0.087156 0.996195 0.0"/>
    <limit effort="100" lower="-0.0445" upper="0.0" velocity="100"/>
  </joint>
  <joint name="left_catch_joint2" type="prismatic">
    <origin rpy="0 0 0" xyz="0.08235 0.078122 -0.005"/>
    <parent link="left_arm_link6"/>
    <child link="left_arm_right_catch"/>
    <axis xyz="0.087156 0.996195 0.0"/>
    <limit effort="100" lower="0.0" upper="0.0445" velocity="100"/>
  </joint>
  <joint name="left_arm_joint6" type="continuous">
    <origin rpy="0 0 0" xyz="0.02884 -0.002523 0.0845"/>
    <parent link="left_arm_link5"/>
    <child link="left_arm_link6"/>
    <axis xyz="-0.996195 0.087156 0.0"/>
  </joint>
  <joint name="left_arm_joint5" type="continuous">
    <origin rpy="0 0 0" xyz="0.067612 -0.033219 -0.0845"/>
    <parent link="left_arm_link4"/>
    <child link="left_arm_link5"/>
    <axis xyz="0.0 0.0 -1.0"/>
  </joint>
  <joint name="left_arm_joint4" type="continuous">
    <origin rpy="0 0 0" xyz="0.244067 -0.021403 -0.06"/>
    <parent link="left_arm_link3"/>
    <child link="left_arm_link4"/>
    <axis xyz="0.087156 0.996195 0.0"/>
  </joint>
  <joint name="left_arm_joint3" type="continuous">
    <origin rpy="0 0 0" xyz="-0.262996 0.023009 0.0"/>
    <parent link="left_arm_link2"/>
    <child link="left_arm_link3"/>
    <axis xyz="0.087156 0.996195 0.0"/>
  </joint>
  <joint name="left_arm_joint2" type="continuous">
    <origin rpy="0 0 0" xyz="0.022299 0.025403 -0.047"/>
    <parent link="left_arm_link1"/>
    <child link="left_arm_link2"/>
    <axis xyz="0.087156 0.996195 0.0"/>
  </joint>
  <joint name="left_arm_joint1" type="continuous">
    <origin rpy="0 0 0" xyz="0.0 0.0 -0.0565"/>
    <parent link="left_arm_base_link"/>
    <child link="left_arm_link1"/>
    <axis xyz="-0.0 -0.0 1.0"/>
  </joint>
  <joint name="arm_left_fixed" type="fixed">
    <!-- 父链接 -->
    <parent link="lift_1"/>
    <!-- 子链接 -->
    <child link="left_arm_base_link"/>
    <!-- 关节的位置和方向（例如原点、方向）-->
    <origin rpy="0 3.1415926 0" xyz="-0.193501 -0.32000 0.083998"/>
  </joint>
  <link name="right_arm_base_link">
    <inertial>
      <origin rpy="0 0 0" xyz="-0.0001456050150032109 -7.271800715889125e-05 -0.03159354340734995"/>
      <mass value="1.1276471378072246"/>
      <inertia ixx="0.000524" ixy="-1e-06" ixz="2e-06" iyy="0.000527" iyz="-2e-06" izz="0.000538"/>
    </inertial>
    <visual>
      <origin rpy="-1.57079632679489 -5.682641097165828e-13 1.4835298641951802" xyz="0.007409306349121554 -0.041273942276757764 -0.09300023656190275"/>
      <geometry>
        <mesh filename="../meshes/lift/arm_base_link.stl" scale="0.001 0.001 0.001"/>
      </geometry>
      <material name="silver"/>
    </visual>
    <collision>
      <origin rpy="-1.57079632679489 -5.682641097165828e-13 1.4835298641951802" xyz="0.007409306349121554 -0.041273942276757764 -0.09300023656190275"/>
      <geometry>
        <mesh filename="../meshes/lift/arm_base_link.stl" scale="0.001 0.001 0.001"/>
      </geometry>
    </collision>
  </link>
  <link name="right_arm_left_catch">
    <inertial>
      <origin rpy="0 0 0" xyz="0.022696371000088422 0.06755851746973854 0.008381661910845134"/>
      <mass value="0.25047156301061513"/>
      <inertia ixx="9.7e-05" ixy="-1.6e-05" ixz="9e-06" iyy="0.000157" iyz="-3e-06" izz="0.000137"/>
    </inertial>
    <visual>
      <origin rpy="-1.5707963267948564 -5.674274719459635e-13 1.483529864195179" xyz="-0.2827978086885289 -0.2179220999653169 -0.13086553021673955"/>
      <geometry>
        <mesh filename="../meshes/lift/arm_left_catch.stl" scale="0.001 0.001 0.001"/>
      </geometry>
      <material name="silver"/>
    </visual>
    <collision>
      <origin rpy="-1.5707963267948564 -5.674274719459635e-13 1.483529864195179" xyz="-0.2827978086885289 -0.2179220999653169 -0.13086553021673955"/>
      <geometry>
        <mesh filename="../meshes/lift/arm_left_catch.stl" scale="0.001 0.001 0.001"/>
      </geometry>
    </collision>
  </link>
  <link name="right_arm_right_catch">
    <inertial>
      <origin rpy="0 0 0" xyz="0.01062064996036352 -0.0704739510881078 0.0022902966101032707"/>
      <mass value="0.2504715624632503"/>
      <inertia ixx="0.000107" ixy="2.5e-05" ixz="-1.9e-05" iyy="0.000152" iyz="3e-06" izz="0.000137"/>
    </inertial>
    <visual>
      <origin rpy="-1.5707963267948528 -5.674877622823835e-13 1.4835298641951784" xyz="-0.3341410986133092 -0.4899139341993404 -0.028033322065217275"/>
      <geometry>
        <mesh filename="../meshes/lift/arm_right_catch.stl" scale="0.001 0.001 0.001"/>
      </geometry>
      <material name="silver"/>
    </visual>
    <collision>
      <origin rpy="-1.5707963267948528 -5.674877622823835e-13 1.4835298641951784" xyz="-0.3341410986133092 -0.4899139341993404 -0.028033322065217275"/>
      <geometry>
        <mesh filename="../meshes/lift/arm_right_catch.stl" scale="0.001 0.001 0.001"/>
      </geometry>
    </collision>
  </link>
  <link name="right_arm_link6">
    <inertial>
      <origin rpy="0 0 0" xyz="0.04606151123037028 -0.00403375833742786 -0.02029844922950161"/>
      <mass value="1.6175866280512115"/>
      <inertia ixx="0.002554" ixy="1e-05" ixz="0.000717" iyy="0.002684" iyz="-5.6e-05" izz="0.001423"/>
    </inertial>
    <visual>
      <origin rpy="-3.1415926535897496 -5.674609506829504e-13 1.4835298641951782" xyz="0.07015096496844125 -0.0940377631493199 0.017299995001154284"/>
      <geometry>
        <mesh filename="../meshes/lift/arm_link6.stl" scale="0.001 0.001 0.001"/>
      </geometry>
      <material name="silver"/>
    </visual>
    <collision>
      <origin rpy="-3.1415926535897496 -5.674609506829504e-13 1.4835298641951782" xyz="0.07015096496844125 -0.0940377631493199 0.017299995001154284"/>
      <geometry>
        <mesh filename="../meshes/lift/arm_link6.stl" scale="0.001 0.001 0.001"/>
      </geometry>
    </collision>
  </link>
  <link name="right_arm_link5">
    <inertial>
      <origin rpy="0 0 0" xyz="0.0035114951739801253 -0.00032438367383951644 0.05339769316683546"/>
      <mass value="1.682735565009155"/>
      <inertia ixx="0.002208" ixy="-3e-06" ixz="-0.000168" iyy="0.002158" iyz="1.4e-05" izz="0.000703"/>
    </inertial>
    <visual>
      <origin rpy="-3.110107982315251e-13 5.550755306658921e-13 -1.3581133125663458" xyz="0.030052794300312463 -0.05494208160627965 -0.057241042913650286"/>
      <geometry>
        <mesh filename="../meshes/lift/arm_link5.stl" scale="0.001 0.001 0.001"/>
      </geometry>
      <material name="silver"/>
    </visual>
    <collision>
      <origin rpy="-3.110107982315251e-13 5.550755306658921e-13 -1.3581133125663458" xyz="0.030052794300312463 -0.05494208160627965 -0.057241042913650286"/>
      <geometry>
        <mesh filename="../meshes/lift/arm_link5.stl" scale="0.001 0.001 0.001"/>
      </geometry>
    </collision>
  </link>
  <link name="right_arm_link4">
    <inertial>
      <origin rpy="0 0 0" xyz="0.039690032456672866 -0.025382085939758787 -0.033369810917050824"/>
      <mass value="0.3614635103426687"/>
      <inertia ixx="0.000648" ixy="6.6e-05" ixz="0.000254" iyy="0.000701" iyz="-8.5e-05" izz="0.000483"/>
    </inertial>
    <visual>
      <origin rpy="-1.5707963267948528 -5.678466258263498e-13 1.4835298641951788" xyz="0.0005892853030446308 -0.027355392579593747 0.13399227229218344"/>
      <geometry>
        <mesh filename="../meshes/lift/arm_link4.stl" scale="0.001 0.001 0.001"/>
      </geometry>
      <material name="silver"/>
    </visual>
    <collision>
      <origin rpy="-1.5707963267948528 -5.678466258263498e-13 1.4835298641951788" xyz="0.0005892853030446308 -0.027355392579593747 0.13399227229218344"/>
      <geometry>
        <mesh filename="../meshes/lift/arm_link4.stl" scale="0.001 0.001 0.001"/>
      </geometry>
    </collision>
  </link>
  <link name="right_arm_link3">
    <inertial>
      <origin rpy="0 0 0" xyz="0.1464097574775916 -0.03950335038970569 -0.055156332017432905"/>
      <mass value="2.8273308884294726"/>
      <inertia ixx="0.002779" ixy="0.001761" ixz="0.002033" iyy="0.026162" iyz="-0.000192" izz="0.025936"/>
    </inertial>
    <visual>
      <origin rpy="-1.5707963267948528 -5.678273122036292e-13 1.4835298641951793" xyz="0.24465628530304592 -0.04875839257959501 0.07399227229217889"/>
      <geometry>
        <mesh filename="../meshes/lift/arm_link3.stl" scale="0.001 0.001 0.001"/>
      </geometry>
      <material name="silver"/>
    </visual>
    <collision>
      <origin rpy="-1.5707963267948528 -5.678273122036292e-13 1.4835298641951793" xyz="0.24465628530304592 -0.04875839257959501 0.07399227229217889"/>
      <geometry>
        <mesh filename="../meshes/lift/arm_link3.stl" scale="0.001 0.001 0.001"/>
      </geometry>
    </collision>
  </link>
  <link name="right_arm_link2">
    <inertial>
      <origin rpy="0 0 0" xyz="-0.13152163105173825 -0.014795828980240422 3.909377899950772e-05"/>
      <mass value="3.2738322976375356"/>
      <inertia ixx="0.002162" ixy="0.003924" ixz="-4e-06" iyy="0.043867" iyz="-0.0" izz="0.044191"/>
    </inertial>
    <visual>
      <origin rpy="-1.5707963267948528 -5.678165582083773e-13 1.4835298641951784" xyz="-0.018339714696967803 -0.02574939257965983 0.07399227229217917"/>
      <geometry>
        <mesh filename="../meshes/lift/arm_link2.stl" scale="0.001 0.001 0.001"/>
      </geometry>
      <material name="silver"/>
    </visual>
    <collision>
      <origin rpy="-1.5707963267948528 -5.678165582083773e-13 1.4835298641951784" xyz="-0.018339714696967803 -0.02574939257965983 0.07399227229217917"/>
      <geometry>
        <mesh filename="../meshes/lift/arm_link2.stl" scale="0.001 0.001 0.001"/>
      </geometry>
    </collision>
  </link>
  <link name="right_arm_link1">
    <inertial>
      <origin rpy="0 0 0" xyz="0.005695029028846315 0.007271965833248688 -0.020896953872813907"/>
      <mass value="0.2814477837021216"/>
      <inertia ixx="0.000303" ixy="-3e-05" ixz="3.9e-05" iyy="0.000139" iyz="2.9e-05" izz="0.00028"/>
    </inertial>
    <visual>
      <origin rpy="-1.570796326794885 -5.65543868255413e-13 1.4835298641951802" xyz="0.003959285303010329 -0.0003463925796654088 0.026992272292183782"/>
      <geometry>
        <mesh filename="../meshes/lift/arm_link1.stl" scale="0.001 0.001 0.001"/>
      </geometry>
      <material name="silver"/>
    </visual>
    <collision>
      <origin rpy="-1.570796326794885 -5.65543868255413e-13 1.4835298641951802" xyz="0.003959285303010329 -0.0003463925796654088 0.026992272292183782"/>
      <geometry>
        <mesh filename="../meshes/lift/arm_link1.stl" scale="0.001 0.001 0.001"/>
      </geometry>
    </collision>
  </link>
  <joint name="right_catch_joint1" type="prismatic">
    <origin rpy="0 0 0" xyz="0.067534 -0.091232 -0.005"/>
    <parent link="right_arm_link6"/>
    <child link="right_arm_left_catch"/>
    <axis xyz="0.087156 0.996195 0.0"/>
    <limit effort="100" lower="-0.0445" upper="0.0" velocity="100"/>
  </joint>
  <joint name="right_catch_joint2" type="prismatic">
    <origin rpy="0 0 0" xyz="0.08235 0.078122 -0.005"/>
    <parent link="right_arm_link6"/>
    <child link="right_arm_right_catch"/>
    <axis xyz="0.087156 0.996195 0.0"/>
    <limit effort="100" lower="0.0" upper="0.0445" velocity="100"/>
  </joint>
  <joint name="right_arm_joint6" type="continuous">
    <origin rpy="0 0 0" xyz="0.02884 -0.002523 0.0845"/>
    <parent link="right_arm_link5"/>
    <child link="right_arm_link6"/>
    <axis xyz="-0.996195 0.087156 0.0"/>
  </joint>
  <joint name="right_arm_joint5" type="continuous">
    <origin rpy="0 0 0" xyz="0.067612 -0.033219 -0.0845"/>
    <parent link="right_arm_link4"/>
    <child link="right_arm_link5"/>
    <axis xyz="0.0 0.0 -1.0"/>
  </joint>
  <joint name="right_arm_joint4" type="continuous">
    <origin rpy="0 0 0" xyz="0.244067 -0.021403 -0.06"/>
    <parent link="right_arm_link3"/>
    <child link="right_arm_link4"/>
    <axis xyz="0.087156 0.996195 0.0"/>
  </joint>
  <joint name="right_arm_joint3" type="continuous">
    <origin rpy="0 0 0" xyz="-0.262996 0.023009 0.0"/>
    <parent link="right_arm_link2"/>
    <child link="right_arm_link3"/>
    <axis xyz="0.087156 0.996195 0.0"/>
  </joint>
  <joint name="right_arm_joint2" type="continuous">
    <origin rpy="0 0 0" xyz="0.022299 0.025403 -0.047"/>
    <parent link="right_arm_link1"/>
    <child link="right_arm_link2"/>
    <axis xyz="0.087156 0.996195 0.0"/>
  </joint>
  <joint name="right_arm_joint1" type="continuous">
    <origin rpy="0 0 0" xyz="0.0 0.0 -0.0565"/>
    <parent link="right_arm_base_link"/>
    <child link="right_arm_link1"/>
    <axis xyz="-0.0 -0.0 1.0"/>
  </joint>
  <joint name="arm_right_fixed" type="fixed">
    <!-- 父链接 -->
    <parent link="lift_1"/>
    <!-- 子链接 -->
    <child link="right_arm_base_link"/>
    <!-- 关节的位置和方向（例如原点、方向）-->
    <origin rpy="0 3.1415926 0" xyz="-0.193501 0.18000 0.083998"/>
  </joint>
</robot>
